Workbook

Sheet Erläuterungen
A1: Bewerbungs-ID | B1: Unternehmen * | C1: Ort | D1: Position * | E1: Referenznummer | F1: Ansprechpartner | G1: Kontakt (E-Mail/Telefon) | H1: Quelle | I1: Art der Bewerbung | J1: Datum der Bewerbung * | K1: Versendete Unterlagen | L1: Aktueller Status * | M1: Status-Datum * | N1: Letzte Kontaktaufnahme | O1: Art der Kontaktaufnahme | P1: Ergebnis der Nachfrage | Q1: Nächster Schritt | R1: Erinnerungsdatum | S1: Priorität | T1: Endergebnis | U1: Notizen | V1: Heute erledigen?
A2: =IF(B2="","","BEW-"&YEAR(J2)&"-"&TEXT(ROW()-1,"000")) | B2: TechSolutions GmbH | C2: Oldenburg | D2: Kaufmännischer Mitarbeiter | E2: REF-001 | F2: Frau Meyer | G2: meyer@musterfirma.de | H2: Unternehmenswebsite | I2: E-Mail | J2: 46133 | K2: Lebenslauf, Anschreiben | L2: Eingangsbestätigung | M2: 46133 | N2: 46139 | O2: E-Mail | P2: Noch keine Rückmeldung | Q2: Telefonisch nachfassen | R2: =IF(OR(L2="Bewerbung versendet",L2="Eingangsbestätigung",L2="Rückmeldung ausstehend"),M2+14,"") | S2: Hoch | U2: Nachfassen nötig | V2: =IF(AND(R2<>"",R2<=TODAY(),T2=""),"ja","")
A3: =IF(B3="","","BEW-"&YEAR(J3)&"-"&TEXT(ROW()-1,"000")) | B3: MedienWerk AG | C3: Bremen | D3: Sachbearbeiter | F3: Herr Schulz | H3: StepStone | I3: Online-Portal | J3: 46126 | K3: Vollständige Unterlagen | L3: Gespräch eingeladen | M3: 46138 | Q3: Gespräch vorbereiten | R3: =IF(OR(L3="Bewerbung versendet",L3="Eingangsbestätigung",L3="Rückmeldung ausstehend"),M3+14,"") | S3: Normal | U3: Einladung erhalten | V3: =IF(AND(R3<>"",R3<=TODAY(),T3=""),"ja","")
A4: =IF(B4="","","BEW-"&YEAR(J4)&"-"&TEXT(ROW()-1,"000")) | B4: Stadtwerke Oldenburg | C4: Delmenhorst | D4: Bürohilfe | H4: Initiativbewerbung | I4: initiativ | J4: 46111 | K4: Lebenslauf | L4: Rückmeldung ausstehend | M4: 46127 | R4: =IF(OR(L4="Bewerbung versendet",L4="Eingangsbestätigung",L4="Rückmeldung ausstehend"),M4+14,"") | S4: Niedrig | U4: Absage dokumentiert | V4: =IF(AND(R4<>"",R4<=TODAY(),T4=""),"ja","")
A5: =IF(B5="","","BEW-"&YEAR(J5)&"-"&TEXT(ROW()-1,"000")) | B5: INN-tegrativ gGmbH | H5: Empfehlung | I5: Persönlich abgegeben | J5: 46175 | K5: Vollständige Unterlagen | L5: Zusage | M5: 46186 | R5: =IF(OR(L5="Bewerbung versendet",L5="Eingangsbestätigung",L5="Rückmeldung ausstehend"),M5+14,"") | V5: =IF(AND(R5<>"",R5<=TODAY(),T5=""),"ja","")
A7: 📋 ANLEITUNG ZUR BEWERBUNGSVERWALTUNG
A8: ⚠️ WICHTIG: Daten regelmäßig sichern! Vor größeren Änderungen eine Kopie der Datei erstellen.
A10: 🔷 ALLGEMEINE HINWEISE | H10: 🔶 STATUSWERTE ERKLÄRT | O10: 🔴 PRIORITÄTEN RICHTIG SETZEN
A11: • Neue Bewerbungen im Blatt 'Bewerbungsübersicht' eintragen • Die Bewerbungs-ID wird automatisch generiert • Das Erinnerungsdatum berechnet sich automatisch • Dropdown-Menüs für einheitliche Eingaben nutzen • Regelmäßig den Status aktualisieren • Blatt 'Heute erledigen' für tägliche Aufgaben prüfen | H11: • Bewerbung versendet → Warten auf Reaktion • Eingangsbestätigung → Bewerbung angekommen • Gespräch eingeladen → Termin vereinbaren! • Gespräch absolviert → Auf Entscheidung warten • Rückmeldung ausstehend → Nachfassen planen • Zusage/Absage → Endergebnis eintragen | O11: 🔴 HOCH: Traumjob, laufendes Verfahren, Frist 🟡 NORMAL: Interessante Stellen, Standardbewerbungen 🟢 NIEDRIG: Backup-Optionen, Initiativbewerbungen
A20: 💡 TIPPS ZUM ERFOLGREICHEN NACHFASSEN | L20: 📑 ÜBERSICHT DER ARBEITSBLÄTTER
A21: ✓ Nach 2 Wochen ohne Rückmeldung freundlich nachfragen ✓ Telefonisch nachfassen ist oft effektiver als E-Mail ✓ Immer die Referenznummer bereithalten ✓ Kurz und höflich bleiben - keine Rechtfertigungen ✓ Ergebnis der Nachfrage sofort dokumentieren | L21: 📊 Bewerbungsübersicht → Alle Bewerbungen verwalten 📅 Heute erledigen → Aktuelle Aufgaben (Filter: ja) 📆 Diese Woche erledigen → Wochenplanung 📋 Erläuterungen → Diese Anleitung (Sie sind hier!) ⚙️ Hilfstabellen → Dropdown-Listen & Vorlagen
A28: 📝 SPALTEN-ERKLÄRUNG (WICHTIGSTE FELDER)
A29: 📌 Bewerbungs-ID: Automatisch generierte eindeutige Nummer (BEW-JJJJ-NNN) 🏢 Unternehmen: Name des Unternehmens, bei dem Sie sich bewerben 📍 Ort: Standort der Stelle 💼 Position: Bezeichnung der ausgeschriebenen Stelle 📅 Datum der Bewerbung: Wann wurde die Bewerbung abgeschickt? 📊 Aktueller Status: Wo steht die Bewerbung gerade? (Dropdown nutzen!) ⏰ Erinnerungsdatum: Automatisch berechnet - wann nachfassen?
A37: 🚀 SCHNELLSTART-CHECKLISTE | L37: ⌨️ NÜTZLICHE EXCEL-TIPPS
A38: ☐ 1. Beispieldaten in 'Bewerbungsübersicht' löschen ☐ 2. Erste eigene Bewerbung eintragen ☐ 3. Priorität und Status festlegen ☐ 4. Täglich 'Heute erledigen' prüfen ☐ 5. Nach Gesprächen sofort Status aktualisieren | L38: • Strg+Pos1: Zum Tabellenanfang springen • Strg+Ende: Zum letzten Eintrag springen • Alt+↓: Dropdown-Liste öffnen • Strg+S: Speichern nicht vergessen! • Filter nutzen: Nur bestimmte Status anzeigen

Sheet Bewerbungsübersicht
A1: Bewerbungs-ID (Automatik) | B1: Unternehmen * | C1: Ort | D1: Position * | E1: Referenz | F1: Ansprechpartner | G1: Kontakt (E-Mail/Telefon) | H1: Quelle | I1: Art Bewerbung | J1: Datum Bewerbung * | K1: Versendete Unterlagen | L1: Aktueller Status * | M1: Status Datum | N1: Letzte Kontaktaufnahme | O1: Art Kontaktaufnahme | P1: Ergebnis Nachfrage | Q1: Nächster Schritt | R1: Erinnerungsdatum (Automatik) | S1: Priorität | T1: Endergebnis | U1: Notizen | V1: Heute erledigen?
A2: =IF(B2="","","BEW-"&YEAR(J2)&"-"&TEXT(ROW()-1,"000")) | B2: TechSolutions GmbH | C2: Hamburg | D2: IT-Administrator | E2: TS-2026-0542 | F2: Frau Dr. Schmidt | G2: hr@techsolutions.de | H2: LinkedIn | I2: Online-Portal | J2: 46165 | K2: Vollständige Unterlagen | L2: Bewerbung versendet | M2: 46186 | N2: 46186 | O2: Persönlich | Q2: Unterlagen prüfen und ergänzen | R2: =IF(OR(L2="Bewerbung versendet",L2="Eingangsbestätigung",L2="Rückmeldung ausstehend"),M2+14,"") | S2: Hoch | U2: Vorstellungsgespräch am 18.06.2026 um 10:00 Uhr | V2: =IF(AND(R2<>"",R2<=TODAY(),T2=""),"ja","")
A3: =IF(B3="","","BEW-"&YEAR(J3)&"-"&TEXT(ROW()-1,"000")) | B3: MedienWerk AG | C3: Berlin | D3: Marketing Manager | E3: MW-1234 | F3: Herr Müller | G3: bewerbung@medienwerk.de | H3: StepStone | I3: E-Mail | J3: 46171 | K3: Lebenslauf, Anschreiben | L3: Bewerbung versendet | M3: 46186 | N3: 46186 | O3: Persönlich | P3: Noch keine Entscheidung | Q3: Nochmals nachfragen | R3: =IF(OR(L3="Bewerbung versendet",L3="Eingangsbestätigung",L3="Rückmeldung ausstehend"),M3+14,"") | S3: Hoch | U3: Sehr interessante Position mit Homeoffice-Option | V3: =IF(AND(R3<>"",R3<=TODAY(),T3=""),"ja","")
A4: =IF(B4="","","BEW-"&YEAR(J4)&"-"&TEXT(ROW()-1,"000")) | B4: Stadtwerke Oldenburg | C4: Oldenburg | D4: Sachbearbeiter Kundenservice | F4: Personalabteilung | G4: personal@stadtwerke-ol.de | H4: Initiativ | I4: Initiativ | J4: 46150 | K4: Lebenslauf, Anschreiben | L4: Bewerbung versendet | M4: 46186 | N4: 46186 | O4: Persönlich | Q4: Nochmals nachfragen | R4: =IF(OR(L4="Bewerbung versendet",L4="Eingangsbestätigung",L4="Rückmeldung ausstehend"),M4+14,"") | S4: Normal | T4: Absage erhalten | U4: Anruf war freundlich, Stelle evtl. erst später frei | V4: =IF(AND(R4<>"",R4<=TODAY(),T4=""),"ja","")
A5: =IF(B5="","","BEW-"&YEAR(J5)&"-"&TEXT(ROW()-1,"000")) | B5: GlobalFinanz Bank | C5: Frankfurt | D5: Kreditsachbearbeiter | E5: GF-2026-089 | F5: Frau Weber | H5: Indeed | I5: Online-Portal | J5: 46140 | K5: Vollständige Unterlagen | L5: Absage | M5: 46155 | R5: =IF(OR(L5="Bewerbung versendet",L5="Eingangsbestätigung",L5="Rückmeldung ausstehend"),M5+14,"") | S5: Normal | T5: Absage erhalten | U5: Absage per E-Mail am 01.06.2026 - andere Bewerber bevorzugt | V5: =IF(AND(R5<>"",R5<=TODAY(),T5=""),"ja","")
A6: =IF(B6="","","BEW-"&YEAR(J6)&"-"&TEXT(ROW()-1,"000")) | B6: Autohaus Schmidt | C6: Bremen | D6: Verkaufsberater | E6: AS-V-2026 | F6: Herr Schmidt | G6: 0421-123456 | H6: Empfehlung | I6: Persönlich abgegeben | J6: 46130 | K6: Lebenslauf | L6: Gespräch absolviert | M6: 46165 | N6: 46165 | O6: Telefon | P6: Zusage! | Q6: Vertrag unterschreiben | R6: =IF(OR(L6="Bewerbung versendet",L6="Eingangsbestätigung",L6="Rückmeldung ausstehend"),M6+14,"") | S6: Hoch | T6: Zusage angenommen | U6: Start am 01.08.2026, Gehalt wie besprochen | V6: =IF(AND(R6<>"",R6<=TODAY(),T6=""),"ja","")

Sheet Heute erledigen
A1: Bewerbungs-ID (Automatik) | B1: Unternehmen * | C1: Ort | D1: Position * | E1: Referenz | F1: Ansprechpartner | G1: Kontakt (E-Mail/Telefon) | H1: Quelle | I1: Art Bewerbung | J1: Datum Bewerbung * | K1: Versendete Unterlagen | L1: Aktueller Status * | M1: Status Datum | N1: Letzte Kontaktaufnahme | O1: Art Kontaktaufnahme | P1: Ergebnis Nachfrage | Q1: Nächster Schritt | R1: Erinnerungsdatum (Automatik) | S1: Priorität | T1: Endergebnis | U1: Notizen | V1: Heute erledigen?
A2: =IFERROR(IF(INDEX(_xlfn._xlws.FILTER(Bewerbungsübersicht!A$2:A$100,(Bewerbungsübersicht!$V$2:$V$100="ja")),ROWS($A$2:A2))=0,"",INDEX(_xlfn._xlws.FILTER(Bewerbungsübersicht!A$2:A$100,(Bewerbungsübersicht!$V$2:$V$100="ja")),ROWS($A$2:A2))),"") | B2: =IFERROR(IF(INDEX(_xlfn._xlws.FILTER(Bewerbungsübersicht!B$2:B$100,(Bewerbungsübersicht!$V$2:$V$100="ja")),ROWS($A$2:A2))=0,"",INDEX(_xlfn._xlws.FILTER(Bewerbungsübersicht!B$2:B$100,(Bewerbungsübersicht!$V$2:$V$100="ja")),ROWS($A$2:A2))),"") | C2: =IFERROR(IF(INDEX(_xlfn._xlws.FILTER(Bewerbungsübersicht!C$2:C$100,(Bewerbungsübersicht!$V$2:$V$100="ja")),ROWS($A$2:A2))=0,"",INDEX(_xlfn._xlws.FILTER(Bewerbungsübersicht!C$2:C$100,(Bewerbungsübersicht!$V$2:$V$100="ja")),ROWS($A$2:A2))),"") | D2: =IFERROR(IF(INDEX(_xlfn._xlws.FILTER(Bewerbungsübersicht!D$2:D$100,(Bewerbungsübersicht!$V$2:$V$100="ja")),ROWS($A$2:A2))=0,"",INDEX(_xlfn._xlws.FILTER(Bewerbungsübersicht!D$2:D$100,(Bewerbungsübersicht!$V$2:$V$100="ja")),ROWS($A$2:A2))),"") | E2: =IFERROR(IF(INDEX(_xlfn._xlws.FILTER(Bewerbungsübersicht!E$2:E$100,(Bewerbungsübersicht!$V$2:$V$100="ja")),ROWS($A$2:A2))=0,"",INDEX(_xlfn._xlws.FILTER(Bewerbungsübersicht!E$2:E$100,(Bewerbungsübersicht!$V$2:$V$100="ja")),ROWS($A$2:A2))),"") | F2: =IFERROR(IF(INDEX(_xlfn._xlws.FILTER(Bewerbungsübersicht!F$2:F$100,(Bewerbungsübersicht!$V$2:$V$100="ja")),ROWS($A$2:A2))=0,"",INDEX(_xlfn._xlws.FILTER(Bewerbungsübersicht!F$2:F$100,(Bewerbungsübersicht!$V$2:$V$100="ja")),ROWS($A$2:A2))),"") | G2: =IFERROR(IF(INDEX(_xlfn._xlws.FILTER(Bewerbungsübersicht!G$2:G$100,(Bewerbungsübersicht!$V$2:$V$100="ja")),ROWS($A$2:A2))=0,"",INDEX(_xlfn._xlws.FILTER(Bewerbungsübersicht!G$2:G$100,(Bewerbungsübersicht!$V$2:$V$100="ja")),ROWS($A$2:A2))),"") | H2: =IFERROR(IF(INDEX(_xlfn._xlws.FILTER(Bewerbungsübersicht!H$2:H$100,(Bewerbungsübersicht!$V$2:$V$100="ja")),ROWS($A$2:A2))=0,"",INDEX(_xlfn._xlws.FILTER(Bewerbungsübersicht!H$2:H$100,(Bewerbungsübersicht!$V$2:$V$100="ja")),ROWS($A$2:A2))),"") | I2: =IFERROR(IF(INDEX(_xlfn._xlws.FILTER(Bewerbungsübersicht!I$2:I$100,(Bewerbungsübersicht!$V$2:$V$100="ja")),ROWS($A$2:A2))=0,"",INDEX(_xlfn._xlws.FILTER(Bewerbungsübersicht!I$2:I$100,(Bewerbungsübersicht!$V$2:$V$100="ja")),ROWS($A$2:A2))),"") | J2: =IFERROR(IF(INDEX(_xlfn._xlws.FILTER(Bewerbungsübersicht!J$2:J$100,(Bewerbungsübersicht!$V$2:$V$100="ja")),ROWS($A$2:A2))=0,"",INDEX(_xlfn._xlws.FILTER(Bewerbungsübersicht!J$2:J$100,(Bewerbungsübersicht!$V$2:$V$100="ja")),ROWS($A$2:A2))),"") | K2: =IFERROR(IF(INDEX(_xlfn._xlws.FILTER(Bewerbungsübersicht!K$2:K$100,(Bewerbungsübersicht!$V$2:$V$100="ja")),ROWS($A$2:A2))=0,"",INDEX(_xlfn._xlws.FILTER(Bewerbungsübersicht!K$2:K$100,(Bewerbungsübersicht!$V$2:$V$100="ja")),ROWS($A$2:A2))),"") | L2: =IFERROR(IF(INDEX(_xlfn._xlws.FILTER(Bewerbungsübersicht!L$2:L$100,(Bewerbungsübersicht!$V$2:$V$100="ja")),ROWS($A$2:A2))=0,"",INDEX(_xlfn._xlws.FILTER(Bewerbungsübersicht!L$2:L$100,(Bewerbungsübersicht!$V$2:$V$100="ja")),ROWS($A$2:A2))),"") | M2: =IFERROR(IF(INDEX(_xlfn._xlws.FILTER(Bewerbungsübersicht!M$2:M$100,(Bewerbungsübersicht!$V$2:$V$100="ja")),ROWS($A$2:A2))=0,"",INDEX(_xlfn._xlws.FILTER(Bewerbungsübersicht!M$2:M$100,(Bewerbungsübersicht!$V$2:$V$100="ja")),ROWS($A$2:A2))),"") | N2: =IFERROR(IF(INDEX(_xlfn._xlws.FILTER(Bewerbungsübersicht!N$2:N$100,(Bewerbungsübersicht!$V$2:$V$100="ja")),ROWS($A$2:A2))=0,"",INDEX(_xlfn._xlws.FILTER(Bewerbungsübersicht!N$2:N$100,(Bewerbungsübersicht!$V$2:$V$100="ja")),ROWS($A$2:A2))),"") | O2: =IFERROR(IF(INDEX(_xlfn._xlws.FILTER(Bewerbungsübersicht!O$2:O$100,(Bewerbungsübersicht!$V$2:$V$100="ja")),ROWS($A$2:A2))=0,"",INDEX(_xlfn._xlws.FILTER(Bewerbungsübersicht!O$2:O$100,(Bewerbungsübersicht!$V$2:$V$100="ja")),ROWS($A$2:A2))),"") | P2: =IFERROR(IF(INDEX(_xlfn._xlws.FILTER(Bewerbungsübersicht!P$2:P$100,(Bewerbungsübersicht!$V$2:$V$100="ja")),ROWS($A$2:A2))=0,"",INDEX(_xlfn._xlws.FILTER(Bewerbungsübersicht!P$2:P$100,(Bewerbungsübersicht!$V$2:$V$100="ja")),ROWS($A$2:A2))),"") | Q2: =IFERROR(IF(INDEX(_xlfn._xlws.FILTER(Bewerbungsübersicht!Q$2:Q$100,(Bewerbungsübersicht!$V$2:$V$100="ja")),ROWS($A$2:A2))=0,"",INDEX(_xlfn._xlws.FILTER(Bewerbungsübersicht!Q$2:Q$100,(Bewerbungsübersicht!$V$2:$V$100="ja")),ROWS($A$2:A2))),"") | R2: =IFERROR(IF(INDEX(_xlfn._xlws.FILTER(Bewerbungsübersicht!R$2:R$100,(Bewerbungsübersicht!$V$2:$V$100="ja")),ROWS($A$2:A2))=0,"",INDEX(_xlfn._xlws.FILTER(Bewerbungsübersicht!R$2:R$100,(Bewerbungsübersicht!$V$2:$V$100="ja")),ROWS($A$2:A2))),"") | S2: =IFERROR(IF(INDEX(_xlfn._xlws.FILTER(Bewerbungsübersicht!S$2:S$100,(Bewerbungsübersicht!$V$2:$V$100="ja")),ROWS($A$2:A2))=0,"",INDEX(_xlfn._xlws.FILTER(Bewerbungsübersicht!S$2:S$100,(Bewerbungsübersicht!$V$2:$V$100="ja")),ROWS($A$2:A2))),"") | T2: =IFERROR(IF(INDEX(_xlfn._xlws.FILTER(Bewerbungsübersicht!T$2:T$100,(Bewerbungsübersicht!$V$2:$V$100="ja")),ROWS($A$2:A2))=0,"",INDEX(_xlfn._xlws.FILTER(Bewerbungsübersicht!T$2:T$100,(Bewerbungsübersicht!$V$2:$V$100="ja")),ROWS($A$2:A2))),"") | U2: =IFERROR(IF(INDEX(_xlfn._xlws.FILTER(Bewerbungsübersicht!U$2:U$100,(Bewerbungsübersicht!$V$2:$V$100="ja")),ROWS($A$2:A2))=0,"",INDEX(_xlfn._xlws.FILTER(Bewerbungsübersicht!U$2:U$100,(Bewerbungsübersicht!$V$2:$V$100="ja")),ROWS($A$2:A2))),"") | V2: =IFERROR(IF(INDEX(_xlfn._xlws.FILTER(Bewerbungsübersicht!V$2:V$100,(Bewerbungsübersicht!$V$2:$V$100="ja")),ROWS($A$2:A2))=0,"",INDEX(_xlfn._xlws.FILTER(Bewerbungsübersicht!V$2:V$100,(Bewerbungsübersicht!$V$2:$V$100="ja")),ROWS($A$2:A2))),"")
A3: =IFERROR(IF(INDEX(_xlfn._xlws.FILTER(Bewerbungsübersicht!A$2:A$100,(Bewerbungsübersicht!$V$2:$V$100="ja")),ROWS($A$2:A3))=0,"",INDEX(_xlfn._xlws.FILTER(Bewerbungsübersicht!A$2:A$100,(Bewerbungsübersicht!$V$2:$V$100="ja")),ROWS($A$2:A3))),"") | B3: =IFERROR(IF(INDEX(_xlfn._xlws.FILTER(Bewerbungsübersicht!B$2:B$100,(Bewerbungsübersicht!$V$2:$V$100="ja")),ROWS($A$2:A3))=0,"",INDEX(_xlfn._xlws.FILTER(Bewerbungsübersicht!B$2:B$100,(Bewerbungsübersicht!$V$2:$V$100="ja")),ROWS($A$2:A3))),"") | C3: =IFERROR(IF(INDEX(_xlfn._xlws.FILTER(Bewerbungsübersicht!C$2:C$100,(Bewerbungsübersicht!$V$2:$V$100="ja")),ROWS($A$2:A3))=0,"",INDEX(_xlfn._xlws.FILTER(Bewerbungsübersicht!C$2:C$100,(Bewerbungsübersicht!$V$2:$V$100="ja")),ROWS($A$2:A3))),"") | D3: =IFERROR(IF(INDEX(_xlfn._xlws.FILTER(Bewerbungsübersicht!D$2:D$100,(Bewerbungsübersicht!$V$2:$V$100="ja")),ROWS($A$2:A3))=0,"",INDEX(_xlfn._xlws.FILTER(Bewerbungsübersicht!D$2:D$100,(Bewerbungsübersicht!$V$2:$V$100="ja")),ROWS($A$2:A3))),"") | E3: =IFERROR(IF(INDEX(_xlfn._xlws.FILTER(Bewerbungsübersicht!E$2:E$100,(Bewerbungsübersicht!$V$2:$V$100="ja")),ROWS($A$2:A3))=0,"",INDEX(_xlfn._xlws.FILTER(Bewerbungsübersicht!E$2:E$100,(Bewerbungsübersicht!$V$2:$V$100="ja")),ROWS($A$2:A3))),"") | F3: =IFERROR(IF(INDEX(_xlfn._xlws.FILTER(Bewerbungsübersicht!F$2:F$100,(Bewerbungsübersicht!$V$2:$V$100="ja")),ROWS($A$2:A3))=0,"",INDEX(_xlfn._xlws.FILTER(Bewerbungsübersicht!F$2:F$100,(Bewerbungsübersicht!$V$2:$V$100="ja")),ROWS($A$2:A3))),"") | G3: =IFERROR(IF(INDEX(_xlfn._xlws.FILTER(Bewerbungsübersicht!G$2:G$100,(Bewerbungsübersicht!$V$2:$V$100="ja")),ROWS($A$2:A3))=0,"",INDEX(_xlfn._xlws.FILTER(Bewerbungsübersicht!G$2:G$100,(Bewerbungsübersicht!$V$2:$V$100="ja")),ROWS($A$2:A3))),"") | H3: =IFERROR(IF(INDEX(_xlfn._xlws.FILTER(Bewerbungsübersicht!H$2:H$100,(Bewerbungsübersicht!$V$2:$V$100="ja")),ROWS($A$2:A3))=0,"",INDEX(_xlfn._xlws.FILTER(Bewerbungsübersicht!H$2:H$100,(Bewerbungsübersicht!$V$2:$V$100="ja")),ROWS($A$2:A3))),"") | I3: =IFERROR(IF(INDEX(_xlfn._xlws.FILTER(Bewerbungsübersicht!I$2:I$100,(Bewerbungsübersicht!$V$2:$V$100="ja")),ROWS($A$2:A3))=0,"",INDEX(_xlfn._xlws.FILTER(Bewerbungsübersicht!I$2:I$100,(Bewerbungsübersicht!$V$2:$V$100="ja")),ROWS($A$2:A3))),"") | J3: =IFERROR(IF(INDEX(_xlfn._xlws.FILTER(Bewerbungsübersicht!J$2:J$100,(Bewerbungsübersicht!$V$2:$V$100="ja")),ROWS($A$2:A3))=0,"",INDEX(_xlfn._xlws.FILTER(Bewerbungsübersicht!J$2:J$100,(Bewerbungsübersicht!$V$2:$V$100="ja")),ROWS($A$2:A3))),"") | K3: =IFERROR(IF(INDEX(_xlfn._xlws.FILTER(Bewerbungsübersicht!K$2:K$100,(Bewerbungsübersicht!$V$2:$V$100="ja")),ROWS($A$2:A3))=0,"",INDEX(_xlfn._xlws.FILTER(Bewerbungsübersicht!K$2:K$100,(Bewerbungsübersicht!$V$2:$V$100="ja")),ROWS($A$2:A3))),"") | L3: =IFERROR(IF(INDEX(_xlfn._xlws.FILTER(Bewerbungsübersicht!L$2:L$100,(Bewerbungsübersicht!$V$2:$V$100="ja")),ROWS($A$2:A3))=0,"",INDEX(_xlfn._xlws.FILTER(Bewerbungsübersicht!L$2:L$100,(Bewerbungsübersicht!$V$2:$V$100="ja")),ROWS($A$2:A3))),"") | M3: =IFERROR(IF(INDEX(_xlfn._xlws.FILTER(Bewerbungsübersicht!M$2:M$100,(Bewerbungsübersicht!$V$2:$V$100="ja")),ROWS($A$2:A3))=0,"",INDEX(_xlfn._xlws.FILTER(Bewerbungsübersicht!M$2:M$100,(Bewerbungsübersicht!$V$2:$V$100="ja")),ROWS($A$2:A3))),"") | N3: =IFERROR(IF(INDEX(_xlfn._xlws.FILTER(Bewerbungsübersicht!N$2:N$100,(Bewerbungsübersicht!$V$2:$V$100="ja")),ROWS($A$2:A3))=0,"",INDEX(_xlfn._xlws.FILTER(Bewerbungsübersicht!N$2:N$100,(Bewerbungsübersicht!$V$2:$V$100="ja")),ROWS($A$2:A3))),"") | O3: =IFERROR(IF(INDEX(_xlfn._xlws.FILTER(Bewerbungsübersicht!O$2:O$100,(Bewerbungsübersicht!$V$2:$V$100="ja")),ROWS($A$2:A3))=0,"",INDEX(_xlfn._xlws.FILTER(Bewerbungsübersicht!O$2:O$100,(Bewerbungsübersicht!$V$2:$V$100="ja")),ROWS($A$2:A3))),"") | P3: =IFERROR(IF(INDEX(_xlfn._xlws.FILTER(Bewerbungsübersicht!P$2:P$100,(Bewerbungsübersicht!$V$2:$V$100="ja")),ROWS($A$2:A3))=0,"",INDEX(_xlfn._xlws.FILTER(Bewerbungsübersicht!P$2:P$100,(Bewerbungsübersicht!$V$2:$V$100="ja")),ROWS($A$2:A3))),"") | Q3: =IFERROR(IF(INDEX(_xlfn._xlws.FILTER(Bewerbungsübersicht!Q$2:Q$100,(Bewerbungsübersicht!$V$2:$V$100="ja")),ROWS($A$2:A3))=0,"",INDEX(_xlfn._xlws.FILTER(Bewerbungsübersicht!Q$2:Q$100,(Bewerbungsübersicht!$V$2:$V$100="ja")),ROWS($A$2:A3))),"") | R3: =IFERROR(IF(INDEX(_xlfn._xlws.FILTER(Bewerbungsübersicht!R$2:R$100,(Bewerbungsübersicht!$V$2:$V$100="ja")),ROWS($A$2:A3))=0,"",INDEX(_xlfn._xlws.FILTER(Bewerbungsübersicht!R$2:R$100,(Bewerbungsübersicht!$V$2:$V$100="ja")),ROWS($A$2:A3))),"") | S3: =IFERROR(IF(INDEX(_xlfn._xlws.FILTER(Bewerbungsübersicht!S$2:S$100,(Bewerbungsübersicht!$V$2:$V$100="ja")),ROWS($A$2:A3))=0,"",INDEX(_xlfn._xlws.FILTER(Bewerbungsübersicht!S$2:S$100,(Bewerbungsübersicht!$V$2:$V$100="ja")),ROWS($A$2:A3))),"") | T3: =IFERROR(IF(INDEX(_xlfn._xlws.FILTER(Bewerbungsübersicht!T$2:T$100,(Bewerbungsübersicht!$V$2:$V$100="ja")),ROWS($A$2:A3))=0,"",INDEX(_xlfn._xlws.FILTER(Bewerbungsübersicht!T$2:T$100,(Bewerbungsübersicht!$V$2:$V$100="ja")),ROWS($A$2:A3))),"") | U3: =IFERROR(IF(INDEX(_xlfn._xlws.FILTER(Bewerbungsübersicht!U$2:U$100,(Bewerbungsübersicht!$V$2:$V$100="ja")),ROWS($A$2:A3))=0,"",INDEX(_xlfn._xlws.FILTER(Bewerbungsübersicht!U$2:U$100,(Bewerbungsübersicht!$V$2:$V$100="ja")),ROWS($A$2:A3))),"") | V3: =IFERROR(IF(INDEX(_xlfn._xlws.FILTER(Bewerbungsübersicht!V$2:V$100,(Bewerbungsübersicht!$V$2:$V$100="ja")),ROWS($A$2:A3))=0,"",INDEX(_xlfn._xlws.FILTER(Bewerbungsübersicht!V$2:V$100,(Bewerbungsübersicht!$V$2:$V$100="ja")),ROWS($A$2:A3))),"")
A4: =IFERROR(IF(INDEX(_xlfn._xlws.FILTER(Bewerbungsübersicht!A$2:A$100,(Bewerbungsübersicht!$V$2:$V$100="ja")),ROWS($A$2:A4))=0,"",INDEX(_xlfn._xlws.FILTER(Bewerbungsübersicht!A$2:A$100,(Bewerbungsübersicht!$V$2:$V$100="ja")),ROWS($A$2:A4))),"") | B4: =IFERROR(IF(INDEX(_xlfn._xlws.FILTER(Bewerbungsübersicht!B$2:B$100,(Bewerbungsübersicht!$V$2:$V$100="ja")),ROWS($A$2:A4))=0,"",INDEX(_xlfn._xlws.FILTER(Bewerbungsübersicht!B$2:B$100,(Bewerbungsübersicht!$V$2:$V$100="ja")),ROWS($A$2:A4))),"") | C4: =IFERROR(IF(INDEX(_xlfn._xlws.FILTER(Bewerbungsübersicht!C$2:C$100,(Bewerbungsübersicht!$V$2:$V$100="ja")),ROWS($A$2:A4))=0,"",INDEX(_xlfn._xlws.FILTER(Bewerbungsübersicht!C$2:C$100,(Bewerbungsübersicht!$V$2:$V$100="ja")),ROWS($A$2:A4))),"") | D4: =IFERROR(IF(INDEX(_xlfn._xlws.FILTER(Bewerbungsübersicht!D$2:D$100,(Bewerbungsübersicht!$V$2:$V$100="ja")),ROWS($A$2:A4))=0,"",INDEX(_xlfn._xlws.FILTER(Bewerbungsübersicht!D$2:D$100,(Bewerbungsübersicht!$V$2:$V$100="ja")),ROWS($A$2:A4))),"") | E4: =IFERROR(IF(INDEX(_xlfn._xlws.FILTER(Bewerbungsübersicht!E$2:E$100,(Bewerbungsübersicht!$V$2:$V$100="ja")),ROWS($A$2:A4))=0,"",INDEX(_xlfn._xlws.FILTER(Bewerbungsübersicht!E$2:E$100,(Bewerbungsübersicht!$V$2:$V$100="ja")),ROWS($A$2:A4))),"") | F4: =IFERROR(IF(INDEX(_xlfn._xlws.FILTER(Bewerbungsübersicht!F$2:F$100,(Bewerbungsübersicht!$V$2:$V$100="ja")),ROWS($A$2:A4))=0,"",INDEX(_xlfn._xlws.FILTER(Bewerbungsübersicht!F$2:F$100,(Bewerbungsübersicht!$V$2:$V$100="ja")),ROWS($A$2:A4))),"") | G4: =IFERROR(IF(INDEX(_xlfn._xlws.FILTER(Bewerbungsübersicht!G$2:G$100,(Bewerbungsübersicht!$V$2:$V$100="ja")),ROWS($A$2:A4))=0,"",INDEX(_xlfn._xlws.FILTER(Bewerbungsübersicht!G$2:G$100,(Bewerbungsübersicht!$V$2:$V$100="ja")),ROWS($A$2:A4))),"") | H4: =IFERROR(IF(INDEX(_xlfn._xlws.FILTER(Bewerbungsübersicht!H$2:H$100,(Bewerbungsübersicht!$V$2:$V$100="ja")),ROWS($A$2:A4))=0,"",INDEX(_xlfn._xlws.FILTER(Bewerbungsübersicht!H$2:H$100,(Bewerbungsübersicht!$V$2:$V$100="ja")),ROWS($A$2:A4))),"") | I4: =IFERROR(IF(INDEX(_xlfn._xlws.FILTER(Bewerbungsübersicht!I$2:I$100,(Bewerbungsübersicht!$V$2:$V$100="ja")),ROWS($A$2:A4))=0,"",INDEX(_xlfn._xlws.FILTER(Bewerbungsübersicht!I$2:I$100,(Bewerbungsübersicht!$V$2:$V$100="ja")),ROWS($A$2:A4))),"") | J4: =IFERROR(IF(INDEX(_xlfn._xlws.FILTER(Bewerbungsübersicht!J$2:J$100,(Bewerbungsübersicht!$V$2:$V$100="ja")),ROWS($A$2:A4))=0,"",INDEX(_xlfn._xlws.FILTER(Bewerbungsübersicht!J$2:J$100,(Bewerbungsübersicht!$V$2:$V$100="ja")),ROWS($A$2:A4))),"") | K4: =IFERROR(IF(INDEX(_xlfn._xlws.FILTER(Bewerbungsübersicht!K$2:K$100,(Bewerbungsübersicht!$V$2:$V$100="ja")),ROWS($A$2:A4))=0,"",INDEX(_xlfn._xlws.FILTER(Bewerbungsübersicht!K$2:K$100,(Bewerbungsübersicht!$V$2:$V$100="ja")),ROWS($A$2:A4))),"") | L4: =IFERROR(IF(INDEX(_xlfn._xlws.FILTER(Bewerbungsübersicht!L$2:L$100,(Bewerbungsübersicht!$V$2:$V$100="ja")),ROWS($A$2:A4))=0,"",INDEX(_xlfn._xlws.FILTER(Bewerbungsübersicht!L$2:L$100,(Bewerbungsübersicht!$V$2:$V$100="ja")),ROWS($A$2:A4))),"") | M4: =IFERROR(IF(INDEX(_xlfn._xlws.FILTER(Bewerbungsübersicht!M$2:M$100,(Bewerbungsübersicht!$V$2:$V$100="ja")),ROWS($A$2:A4))=0,"",INDEX(_xlfn._xlws.FILTER(Bewerbungsübersicht!M$2:M$100,(Bewerbungsübersicht!$V$2:$V$100="ja")),ROWS($A$2:A4))),"") | N4: =IFERROR(IF(INDEX(_xlfn._xlws.FILTER(Bewerbungsübersicht!N$2:N$100,(Bewerbungsübersicht!$V$2:$V$100="ja")),ROWS($A$2:A4))=0,"",INDEX(_xlfn._xlws.FILTER(Bewerbungsübersicht!N$2:N$100,(Bewerbungsübersicht!$V$2:$V$100="ja")),ROWS($A$2:A4))),"") | O4: =IFERROR(IF(INDEX(_xlfn._xlws.FILTER(Bewerbungsübersicht!O$2:O$100,(Bewerbungsübersicht!$V$2:$V$100="ja")),ROWS($A$2:A4))=0,"",INDEX(_xlfn._xlws.FILTER(Bewerbungsübersicht!O$2:O$100,(Bewerbungsübersicht!$V$2:$V$100="ja")),ROWS($A$2:A4))),"") | P4: =IFERROR(IF(INDEX(_xlfn._xlws.FILTER(Bewerbungsübersicht!P$2:P$100,(Bewerbungsübersicht!$V$2:$V$100="ja")),ROWS($A$2:A4))=0,"",INDEX(_xlfn._xlws.FILTER(Bewerbungsübersicht!P$2:P$100,(Bewerbungsübersicht!$V$2:$V$100="ja")),ROWS($A$2:A4))),"") | Q4: =IFERROR(IF(INDEX(_xlfn._xlws.FILTER(Bewerbungsübersicht!Q$2:Q$100,(Bewerbungsübersicht!$V$2:$V$100="ja")),ROWS($A$2:A4))=0,"",INDEX(_xlfn._xlws.FILTER(Bewerbungsübersicht!Q$2:Q$100,(Bewerbungsübersicht!$V$2:$V$100="ja")),ROWS($A$2:A4))),"") | R4: =IFERROR(IF(INDEX(_xlfn._xlws.FILTER(Bewerbungsübersicht!R$2:R$100,(Bewerbungsübersicht!$V$2:$V$100="ja")),ROWS($A$2:A4))=0,"",INDEX(_xlfn._xlws.FILTER(Bewerbungsübersicht!R$2:R$100,(Bewerbungsübersicht!$V$2:$V$100="ja")),ROWS($A$2:A4))),"") | S4: =IFERROR(IF(INDEX(_xlfn._xlws.FILTER(Bewerbungsübersicht!S$2:S$100,(Bewerbungsübersicht!$V$2:$V$100="ja")),ROWS($A$2:A4))=0,"",INDEX(_xlfn._xlws.FILTER(Bewerbungsübersicht!S$2:S$100,(Bewerbungsübersicht!$V$2:$V$100="ja")),ROWS($A$2:A4))),"") | T4: =IFERROR(IF(INDEX(_xlfn._xlws.FILTER(Bewerbungsübersicht!T$2:T$100,(Bewerbungsübersicht!$V$2:$V$100="ja")),ROWS($A$2:A4))=0,"",INDEX(_xlfn._xlws.FILTER(Bewerbungsübersicht!T$2:T$100,(Bewerbungsübersicht!$V$2:$V$100="ja")),ROWS($A$2:A4))),"") | U4: =IFERROR(IF(INDEX(_xlfn._xlws.FILTER(Bewerbungsübersicht!U$2:U$100,(Bewerbungsübersicht!$V$2:$V$100="ja")),ROWS($A$2:A4))=0,"",INDEX(_xlfn._xlws.FILTER(Bewerbungsübersicht!U$2:U$100,(Bewerbungsübersicht!$V$2:$V$100="ja")),ROWS($A$2:A4))),"") | V4: =IFERROR(IF(INDEX(_xlfn._xlws.FILTER(Bewerbungsübersicht!V$2:V$100,(Bewerbungsübersicht!$V$2:$V$100="ja")),ROWS($A$2:A4))=0,"",INDEX(_xlfn._xlws.FILTER(Bewerbungsübersicht!V$2:V$100,(Bewerbungsübersicht!$V$2:$V$100="ja")),ROWS($A$2:A4))),"")
A5: =IFERROR(IF(INDEX(_xlfn._xlws.FILTER(Bewerbungsübersicht!A$2:A$100,(Bewerbungsübersicht!$V$2:$V$100="ja")),ROWS($A$2:A5))=0,"",INDEX(_xlfn._xlws.FILTER(Bewerbungsübersicht!A$2:A$100,(Bewerbungsübersicht!$V$2:$V$100="ja")),ROWS($A$2:A5))),"") | B5: =IFERROR(IF(INDEX(_xlfn._xlws.FILTER(Bewerbungsübersicht!B$2:B$100,(Bewerbungsübersicht!$V$2:$V$100="ja")),ROWS($A$2:A5))=0,"",INDEX(_xlfn._xlws.FILTER(Bewerbungsübersicht!B$2:B$100,(Bewerbungsübersicht!$V$2:$V$100="ja")),ROWS($A$2:A5))),"") | C5: =IFERROR(IF(INDEX(_xlfn._xlws.FILTER(Bewerbungsübersicht!C$2:C$100,(Bewerbungsübersicht!$V$2:$V$100="ja")),ROWS($A$2:A5))=0,"",INDEX(_xlfn._xlws.FILTER(Bewerbungsübersicht!C$2:C$100,(Bewerbungsübersicht!$V$2:$V$100="ja")),ROWS($A$2:A5))),"") | D5: =IFERROR(IF(INDEX(_xlfn._xlws.FILTER(Bewerbungsübersicht!D$2:D$100,(Bewerbungsübersicht!$V$2:$V$100="ja")),ROWS($A$2:A5))=0,"",INDEX(_xlfn._xlws.FILTER(Bewerbungsübersicht!D$2:D$100,(Bewerbungsübersicht!$V$2:$V$100="ja")),ROWS($A$2:A5))),"") | E5: =IFERROR(IF(INDEX(_xlfn._xlws.FILTER(Bewerbungsübersicht!E$2:E$100,(Bewerbungsübersicht!$V$2:$V$100="ja")),ROWS($A$2:A5))=0,"",INDEX(_xlfn._xlws.FILTER(Bewerbungsübersicht!E$2:E$100,(Bewerbungsübersicht!$V$2:$V$100="ja")),ROWS($A$2:A5))),"") | F5: =IFERROR(IF(INDEX(_xlfn._xlws.FILTER(Bewerbungsübersicht!F$2:F$100,(Bewerbungsübersicht!$V$2:$V$100="ja")),ROWS($A$2:A5))=0,"",INDEX(_xlfn._xlws.FILTER(Bewerbungsübersicht!F$2:F$100,(Bewerbungsübersicht!$V$2:$V$100="ja")),ROWS($A$2:A5))),"") | G5: =IFERROR(IF(INDEX(_xlfn._xlws.FILTER(Bewerbungsübersicht!G$2:G$100,(Bewerbungsübersicht!$V$2:$V$100="ja")),ROWS($A$2:A5))=0,"",INDEX(_xlfn._xlws.FILTER(Bewerbungsübersicht!G$2:G$100,(Bewerbungsübersicht!$V$2:$V$100="ja")),ROWS($A$2:A5))),"") | H5: =IFERROR(IF(INDEX(_xlfn._xlws.FILTER(Bewerbungsübersicht!H$2:H$100,(Bewerbungsübersicht!$V$2:$V$100="ja")),ROWS($A$2:A5))=0,"",INDEX(_xlfn._xlws.FILTER(Bewerbungsübersicht!H$2:H$100,(Bewerbungsübersicht!$V$2:$V$100="ja")),ROWS($A$2:A5))),"") | I5: =IFERROR(IF(INDEX(_xlfn._xlws.FILTER(Bewerbungsübersicht!I$2:I$100,(Bewerbungsübersicht!$V$2:$V$100="ja")),ROWS($A$2:A5))=0,"",INDEX(_xlfn._xlws.FILTER(Bewerbungsübersicht!I$2:I$100,(Bewerbungsübersicht!$V$2:$V$100="ja")),ROWS($A$2:A5))),"") | J5: =IFERROR(IF(INDEX(_xlfn._xlws.FILTER(Bewerbungsübersicht!J$2:J$100,(Bewerbungsübersicht!$V$2:$V$100="ja")),ROWS($A$2:A5))=0,"",INDEX(_xlfn._xlws.FILTER(Bewerbungsübersicht!J$2:J$100,(Bewerbungsübersicht!$V$2:$V$100="ja")),ROWS($A$2:A5))),"") | K5: =IFERROR(IF(INDEX(_xlfn._xlws.FILTER(Bewerbungsübersicht!K$2:K$100,(Bewerbungsübersicht!$V$2:$V$100="ja")),ROWS($A$2:A5))=0,"",INDEX(_xlfn._xlws.FILTER(Bewerbungsübersicht!K$2:K$100,(Bewerbungsübersicht!$V$2:$V$100="ja")),ROWS($A$2:A5))),"") | L5: =IFERROR(IF(INDEX(_xlfn._xlws.FILTER(Bewerbungsübersicht!L$2:L$100,(Bewerbungsübersicht!$V$2:$V$100="ja")),ROWS($A$2:A5))=0,"",INDEX(_xlfn._xlws.FILTER(Bewerbungsübersicht!L$2:L$100,(Bewerbungsübersicht!$V$2:$V$100="ja")),ROWS($A$2:A5))),"") | M5: =IFERROR(IF(INDEX(_xlfn._xlws.FILTER(Bewerbungsübersicht!M$2:M$100,(Bewerbungsübersicht!$V$2:$V$100="ja")),ROWS($A$2:A5))=0,"",INDEX(_xlfn._xlws.FILTER(Bewerbungsübersicht!M$2:M$100,(Bewerbungsübersicht!$V$2:$V$100="ja")),ROWS($A$2:A5))),"") | N5: =IFERROR(IF(INDEX(_xlfn._xlws.FILTER(Bewerbungsübersicht!N$2:N$100,(Bewerbungsübersicht!$V$2:$V$100="ja")),ROWS($A$2:A5))=0,"",INDEX(_xlfn._xlws.FILTER(Bewerbungsübersicht!N$2:N$100,(Bewerbungsübersicht!$V$2:$V$100="ja")),ROWS($A$2:A5))),"") | O5: =IFERROR(IF(INDEX(_xlfn._xlws.FILTER(Bewerbungsübersicht!O$2:O$100,(Bewerbungsübersicht!$V$2:$V$100="ja")),ROWS($A$2:A5))=0,"",INDEX(_xlfn._xlws.FILTER(Bewerbungsübersicht!O$2:O$100,(Bewerbungsübersicht!$V$2:$V$100="ja")),ROWS($A$2:A5))),"") | P5: =IFERROR(IF(INDEX(_xlfn._xlws.FILTER(Bewerbungsübersicht!P$2:P$100,(Bewerbungsübersicht!$V$2:$V$100="ja")),ROWS($A$2:A5))=0,"",INDEX(_xlfn._xlws.FILTER(Bewerbungsübersicht!P$2:P$100,(Bewerbungsübersicht!$V$2:$V$100="ja")),ROWS($A$2:A5))),"") | Q5: =IFERROR(IF(INDEX(_xlfn._xlws.FILTER(Bewerbungsübersicht!Q$2:Q$100,(Bewerbungsübersicht!$V$2:$V$100="ja")),ROWS($A$2:A5))=0,"",INDEX(_xlfn._xlws.FILTER(Bewerbungsübersicht!Q$2:Q$100,(Bewerbungsübersicht!$V$2:$V$100="ja")),ROWS($A$2:A5))),"") | R5: =IFERROR(IF(INDEX(_xlfn._xlws.FILTER(Bewerbungsübersicht!R$2:R$100,(Bewerbungsübersicht!$V$2:$V$100="ja")),ROWS($A$2:A5))=0,"",INDEX(_xlfn._xlws.FILTER(Bewerbungsübersicht!R$2:R$100,(Bewerbungsübersicht!$V$2:$V$100="ja")),ROWS($A$2:A5))),"") | S5: =IFERROR(IF(INDEX(_xlfn._xlws.FILTER(Bewerbungsübersicht!S$2:S$100,(Bewerbungsübersicht!$V$2:$V$100="ja")),ROWS($A$2:A5))=0,"",INDEX(_xlfn._xlws.FILTER(Bewerbungsübersicht!S$2:S$100,(Bewerbungsübersicht!$V$2:$V$100="ja")),ROWS($A$2:A5))),"") | T5: =IFERROR(IF(INDEX(_xlfn._xlws.FILTER(Bewerbungsübersicht!T$2:T$100,(Bewerbungsübersicht!$V$2:$V$100="ja")),ROWS($A$2:A5))=0,"",INDEX(_xlfn._xlws.FILTER(Bewerbungsübersicht!T$2:T$100,(Bewerbungsübersicht!$V$2:$V$100="ja")),ROWS($A$2:A5))),"") | U5: =IFERROR(IF(INDEX(_xlfn._xlws.FILTER(Bewerbungsübersicht!U$2:U$100,(Bewerbungsübersicht!$V$2:$V$100="ja")),ROWS($A$2:A5))=0,"",INDEX(_xlfn._xlws.FILTER(Bewerbungsübersicht!U$2:U$100,(Bewerbungsübersicht!$V$2:$V$100="ja")),ROWS($A$2:A5))),"") | V5: =IFERROR(IF(INDEX(_xlfn._xlws.FILTER(Bewerbungsübersicht!V$2:V$100,(Bewerbungsübersicht!$V$2:$V$100="ja")),ROWS($A$2:A5))=0,"",INDEX(_xlfn._xlws.FILTER(Bewerbungsübersicht!V$2:V$100,(Bewerbungsübersicht!$V$2:$V$100="ja")),ROWS($A$2:A5))),"")
A6: =IFERROR(IF(INDEX(_xlfn._xlws.FILTER(Bewerbungsübersicht!A$2:A$100,(Bewerbungsübersicht!$V$2:$V$100="ja")),ROWS($A$2:A6))=0,"",INDEX(_xlfn._xlws.FILTER(Bewerbungsübersicht!A$2:A$100,(Bewerbungsübersicht!$V$2:$V$100="ja")),ROWS($A$2:A6))),"") | B6: =IFERROR(IF(INDEX(_xlfn._xlws.FILTER(Bewerbungsübersicht!B$2:B$100,(Bewerbungsübersicht!$V$2:$V$100="ja")),ROWS($A$2:A6))=0,"",INDEX(_xlfn._xlws.FILTER(Bewerbungsübersicht!B$2:B$100,(Bewerbungsübersicht!$V$2:$V$100="ja")),ROWS($A$2:A6))),"") | C6: =IFERROR(IF(INDEX(_xlfn._xlws.FILTER(Bewerbungsübersicht!C$2:C$100,(Bewerbungsübersicht!$V$2:$V$100="ja")),ROWS($A$2:A6))=0,"",INDEX(_xlfn._xlws.FILTER(Bewerbungsübersicht!C$2:C$100,(Bewerbungsübersicht!$V$2:$V$100="ja")),ROWS($A$2:A6))),"") | D6: =IFERROR(IF(INDEX(_xlfn._xlws.FILTER(Bewerbungsübersicht!D$2:D$100,(Bewerbungsübersicht!$V$2:$V$100="ja")),ROWS($A$2:A6))=0,"",INDEX(_xlfn._xlws.FILTER(Bewerbungsübersicht!D$2:D$100,(Bewerbungsübersicht!$V$2:$V$100="ja")),ROWS($A$2:A6))),"") | E6: =IFERROR(IF(INDEX(_xlfn._xlws.FILTER(Bewerbungsübersicht!E$2:E$100,(Bewerbungsübersicht!$V$2:$V$100="ja")),ROWS($A$2:A6))=0,"",INDEX(_xlfn._xlws.FILTER(Bewerbungsübersicht!E$2:E$100,(Bewerbungsübersicht!$V$2:$V$100="ja")),ROWS($A$2:A6))),"") | F6: =IFERROR(IF(INDEX(_xlfn._xlws.FILTER(Bewerbungsübersicht!F$2:F$100,(Bewerbungsübersicht!$V$2:$V$100="ja")),ROWS($A$2:A6))=0,"",INDEX(_xlfn._xlws.FILTER(Bewerbungsübersicht!F$2:F$100,(Bewerbungsübersicht!$V$2:$V$100="ja")),ROWS($A$2:A6))),"") | G6: =IFERROR(IF(INDEX(_xlfn._xlws.FILTER(Bewerbungsübersicht!G$2:G$100,(Bewerbungsübersicht!$V$2:$V$100="ja")),ROWS($A$2:A6))=0,"",INDEX(_xlfn._xlws.FILTER(Bewerbungsübersicht!G$2:G$100,(Bewerbungsübersicht!$V$2:$V$100="ja")),ROWS($A$2:A6))),"") | H6: =IFERROR(IF(INDEX(_xlfn._xlws.FILTER(Bewerbungsübersicht!H$2:H$100,(Bewerbungsübersicht!$V$2:$V$100="ja")),ROWS($A$2:A6))=0,"",INDEX(_xlfn._xlws.FILTER(Bewerbungsübersicht!H$2:H$100,(Bewerbungsübersicht!$V$2:$V$100="ja")),ROWS($A$2:A6))),"") | I6: =IFERROR(IF(INDEX(_xlfn._xlws.FILTER(Bewerbungsübersicht!I$2:I$100,(Bewerbungsübersicht!$V$2:$V$100="ja")),ROWS($A$2:A6))=0,"",INDEX(_xlfn._xlws.FILTER(Bewerbungsübersicht!I$2:I$100,(Bewerbungsübersicht!$V$2:$V$100="ja")),ROWS($A$2:A6))),"") | J6: =IFERROR(IF(INDEX(_xlfn._xlws.FILTER(Bewerbungsübersicht!J$2:J$100,(Bewerbungsübersicht!$V$2:$V$100="ja")),ROWS($A$2:A6))=0,"",INDEX(_xlfn._xlws.FILTER(Bewerbungsübersicht!J$2:J$100,(Bewerbungsübersicht!$V$2:$V$100="ja")),ROWS($A$2:A6))),"") | K6: =IFERROR(IF(INDEX(_xlfn._xlws.FILTER(Bewerbungsübersicht!K$2:K$100,(Bewerbungsübersicht!$V$2:$V$100="ja")),ROWS($A$2:A6))=0,"",INDEX(_xlfn._xlws.FILTER(Bewerbungsübersicht!K$2:K$100,(Bewerbungsübersicht!$V$2:$V$100="ja")),ROWS($A$2:A6))),"") | L6: =IFERROR(IF(INDEX(_xlfn._xlws.FILTER(Bewerbungsübersicht!L$2:L$100,(Bewerbungsübersicht!$V$2:$V$100="ja")),ROWS($A$2:A6))=0,"",INDEX(_xlfn._xlws.FILTER(Bewerbungsübersicht!L$2:L$100,(Bewerbungsübersicht!$V$2:$V$100="ja")),ROWS($A$2:A6))),"") | M6: =IFERROR(IF(INDEX(_xlfn._xlws.FILTER(Bewerbungsübersicht!M$2:M$100,(Bewerbungsübersicht!$V$2:$V$100="ja")),ROWS($A$2:A6))=0,"",INDEX(_xlfn._xlws.FILTER(Bewerbungsübersicht!M$2:M$100,(Bewerbungsübersicht!$V$2:$V$100="ja")),ROWS($A$2:A6))),"") | N6: =IFERROR(IF(INDEX(_xlfn._xlws.FILTER(Bewerbungsübersicht!N$2:N$100,(Bewerbungsübersicht!$V$2:$V$100="ja")),ROWS($A$2:A6))=0,"",INDEX(_xlfn._xlws.FILTER(Bewerbungsübersicht!N$2:N$100,(Bewerbungsübersicht!$V$2:$V$100="ja")),ROWS($A$2:A6))),"") | O6: =IFERROR(IF(INDEX(_xlfn._xlws.FILTER(Bewerbungsübersicht!O$2:O$100,(Bewerbungsübersicht!$V$2:$V$100="ja")),ROWS($A$2:A6))=0,"",INDEX(_xlfn._xlws.FILTER(Bewerbungsübersicht!O$2:O$100,(Bewerbungsübersicht!$V$2:$V$100="ja")),ROWS($A$2:A6))),"") | P6: =IFERROR(IF(INDEX(_xlfn._xlws.FILTER(Bewerbungsübersicht!P$2:P$100,(Bewerbungsübersicht!$V$2:$V$100="ja")),ROWS($A$2:A6))=0,"",INDEX(_xlfn._xlws.FILTER(Bewerbungsübersicht!P$2:P$100,(Bewerbungsübersicht!$V$2:$V$100="ja")),ROWS($A$2:A6))),"") | Q6: =IFERROR(IF(INDEX(_xlfn._xlws.FILTER(Bewerbungsübersicht!Q$2:Q$100,(Bewerbungsübersicht!$V$2:$V$100="ja")),ROWS($A$2:A6))=0,"",INDEX(_xlfn._xlws.FILTER(Bewerbungsübersicht!Q$2:Q$100,(Bewerbungsübersicht!$V$2:$V$100="ja")),ROWS($A$2:A6))),"") | R6: =IFERROR(IF(INDEX(_xlfn._xlws.FILTER(Bewerbungsübersicht!R$2:R$100,(Bewerbungsübersicht!$V$2:$V$100="ja")),ROWS($A$2:A6))=0,"",INDEX(_xlfn._xlws.FILTER(Bewerbungsübersicht!R$2:R$100,(Bewerbungsübersicht!$V$2:$V$100="ja")),ROWS($A$2:A6))),"") | S6: =IFERROR(IF(INDEX(_xlfn._xlws.FILTER(Bewerbungsübersicht!S$2:S$100,(Bewerbungsübersicht!$V$2:$V$100="ja")),ROWS($A$2:A6))=0,"",INDEX(_xlfn._xlws.FILTER(Bewerbungsübersicht!S$2:S$100,(Bewerbungsübersicht!$V$2:$V$100="ja")),ROWS($A$2:A6))),"") | T6: =IFERROR(IF(INDEX(_xlfn._xlws.FILTER(Bewerbungsübersicht!T$2:T$100,(Bewerbungsübersicht!$V$2:$V$100="ja")),ROWS($A$2:A6))=0,"",INDEX(_xlfn._xlws.FILTER(Bewerbungsübersicht!T$2:T$100,(Bewerbungsübersicht!$V$2:$V$100="ja")),ROWS($A$2:A6))),"") | U6: =IFERROR(IF(INDEX(_xlfn._xlws.FILTER(Bewerbungsübersicht!U$2:U$100,(Bewerbungsübersicht!$V$2:$V$100="ja")),ROWS($A$2:A6))=0,"",INDEX(_xlfn._xlws.FILTER(Bewerbungsübersicht!U$2:U$100,(Bewerbungsübersicht!$V$2:$V$100="ja")),ROWS($A$2:A6))),"") | V6: =IFERROR(IF(INDEX(_xlfn._xlws.FILTER(Bewerbungsübersicht!V$2:V$100,(Bewerbungsübersicht!$V$2:$V$100="ja")),ROWS($A$2:A6))=0,"",INDEX(_xlfn._xlws.FILTER(Bewerbungsübersicht!V$2:V$100,(Bewerbungsübersicht!$V$2:$V$100="ja")),ROWS($A$2:A6))),"")
A7: =IFERROR(IF(INDEX(_xlfn._xlws.FILTER(Bewerbungsübersicht!A$2:A$100,(Bewerbungsübersicht!$V$2:$V$100="ja")),ROWS($A$2:A7))=0,"",INDEX(_xlfn._xlws.FILTER(Bewerbungsübersicht!A$2:A$100,(Bewerbungsübersicht!$V$2:$V$100="ja")),ROWS($A$2:A7))),"") | B7: =IFERROR(IF(INDEX(_xlfn._xlws.FILTER(Bewerbungsübersicht!B$2:B$100,(Bewerbungsübersicht!$V$2:$V$100="ja")),ROWS($A$2:A7))=0,"",INDEX(_xlfn._xlws.FILTER(Bewerbungsübersicht!B$2:B$100,(Bewerbungsübersicht!$V$2:$V$100="ja")),ROWS($A$2:A7))),"") | C7: =IFERROR(IF(INDEX(_xlfn._xlws.FILTER(Bewerbungsübersicht!C$2:C$100,(Bewerbungsübersicht!$V$2:$V$100="ja")),ROWS($A$2:A7))=0,"",INDEX(_xlfn._xlws.FILTER(Bewerbungsübersicht!C$2:C$100,(Bewerbungsübersicht!$V$2:$V$100="ja")),ROWS($A$2:A7))),"") | D7: =IFERROR(IF(INDEX(_xlfn._xlws.FILTER(Bewerbungsübersicht!D$2:D$100,(Bewerbungsübersicht!$V$2:$V$100="ja")),ROWS($A$2:A7))=0,"",INDEX(_xlfn._xlws.FILTER(Bewerbungsübersicht!D$2:D$100,(Bewerbungsübersicht!$V$2:$V$100="ja")),ROWS($A$2:A7))),"") | E7: =IFERROR(IF(INDEX(_xlfn._xlws.FILTER(Bewerbungsübersicht!E$2:E$100,(Bewerbungsübersicht!$V$2:$V$100="ja")),ROWS($A$2:A7))=0,"",INDEX(_xlfn._xlws.FILTER(Bewerbungsübersicht!E$2:E$100,(Bewerbungsübersicht!$V$2:$V$100="ja")),ROWS($A$2:A7))),"") | F7: =IFERROR(IF(INDEX(_xlfn._xlws.FILTER(Bewerbungsübersicht!F$2:F$100,(Bewerbungsübersicht!$V$2:$V$100="ja")),ROWS($A$2:A7))=0,"",INDEX(_xlfn._xlws.FILTER(Bewerbungsübersicht!F$2:F$100,(Bewerbungsübersicht!$V$2:$V$100="ja")),ROWS($A$2:A7))),"") | G7: =IFERROR(IF(INDEX(_xlfn._xlws.FILTER(Bewerbungsübersicht!G$2:G$100,(Bewerbungsübersicht!$V$2:$V$100="ja")),ROWS($A$2:A7))=0,"",INDEX(_xlfn._xlws.FILTER(Bewerbungsübersicht!G$2:G$100,(Bewerbungsübersicht!$V$2:$V$100="ja")),ROWS($A$2:A7))),"") | H7: =IFERROR(IF(INDEX(_xlfn._xlws.FILTER(Bewerbungsübersicht!H$2:H$100,(Bewerbungsübersicht!$V$2:$V$100="ja")),ROWS($A$2:A7))=0,"",INDEX(_xlfn._xlws.FILTER(Bewerbungsübersicht!H$2:H$100,(Bewerbungsübersicht!$V$2:$V$100="ja")),ROWS($A$2:A7))),"") | I7: =IFERROR(IF(INDEX(_xlfn._xlws.FILTER(Bewerbungsübersicht!I$2:I$100,(Bewerbungsübersicht!$V$2:$V$100="ja")),ROWS($A$2:A7))=0,"",INDEX(_xlfn._xlws.FILTER(Bewerbungsübersicht!I$2:I$100,(Bewerbungsübersicht!$V$2:$V$100="ja")),ROWS($A$2:A7))),"") | J7: =IFERROR(IF(INDEX(_xlfn._xlws.FILTER(Bewerbungsübersicht!J$2:J$100,(Bewerbungsübersicht!$V$2:$V$100="ja")),ROWS($A$2:A7))=0,"",INDEX(_xlfn._xlws.FILTER(Bewerbungsübersicht!J$2:J$100,(Bewerbungsübersicht!$V$2:$V$100="ja")),ROWS($A$2:A7))),"") | K7: =IFERROR(IF(INDEX(_xlfn._xlws.FILTER(Bewerbungsübersicht!K$2:K$100,(Bewerbungsübersicht!$V$2:$V$100="ja")),ROWS($A$2:A7))=0,"",INDEX(_xlfn._xlws.FILTER(Bewerbungsübersicht!K$2:K$100,(Bewerbungsübersicht!$V$2:$V$100="ja")),ROWS($A$2:A7))),"") | L7: =IFERROR(IF(INDEX(_xlfn._xlws.FILTER(Bewerbungsübersicht!L$2:L$100,(Bewerbungsübersicht!$V$2:$V$100="ja")),ROWS($A$2:A7))=0,"",INDEX(_xlfn._xlws.FILTER(Bewerbungsübersicht!L$2:L$100,(Bewerbungsübersicht!$V$2:$V$100="ja")),ROWS($A$2:A7))),"") | M7: =IFERROR(IF(INDEX(_xlfn._xlws.FILTER(Bewerbungsübersicht!M$2:M$100,(Bewerbungsübersicht!$V$2:$V$100="ja")),ROWS($A$2:A7))=0,"",INDEX(_xlfn._xlws.FILTER(Bewerbungsübersicht!M$2:M$100,(Bewerbungsübersicht!$V$2:$V$100="ja")),ROWS($A$2:A7))),"") | N7: =IFERROR(IF(INDEX(_xlfn._xlws.FILTER(Bewerbungsübersicht!N$2:N$100,(Bewerbungsübersicht!$V$2:$V$100="ja")),ROWS($A$2:A7))=0,"",INDEX(_xlfn._xlws.FILTER(Bewerbungsübersicht!N$2:N$100,(Bewerbungsübersicht!$V$2:$V$100="ja")),ROWS($A$2:A7))),"") | O7: =IFERROR(IF(INDEX(_xlfn._xlws.FILTER(Bewerbungsübersicht!O$2:O$100,(Bewerbungsübersicht!$V$2:$V$100="ja")),ROWS($A$2:A7))=0,"",INDEX(_xlfn._xlws.FILTER(Bewerbungsübersicht!O$2:O$100,(Bewerbungsübersicht!$V$2:$V$100="ja")),ROWS($A$2:A7))),"") | P7: =IFERROR(IF(INDEX(_xlfn._xlws.FILTER(Bewerbungsübersicht!P$2:P$100,(Bewerbungsübersicht!$V$2:$V$100="ja")),ROWS($A$2:A7))=0,"",INDEX(_xlfn._xlws.FILTER(Bewerbungsübersicht!P$2:P$100,(Bewerbungsübersicht!$V$2:$V$100="ja")),ROWS($A$2:A7))),"") | Q7: =IFERROR(IF(INDEX(_xlfn._xlws.FILTER(Bewerbungsübersicht!Q$2:Q$100,(Bewerbungsübersicht!$V$2:$V$100="ja")),ROWS($A$2:A7))=0,"",INDEX(_xlfn._xlws.FILTER(Bewerbungsübersicht!Q$2:Q$100,(Bewerbungsübersicht!$V$2:$V$100="ja")),ROWS($A$2:A7))),"") | R7: =IFERROR(IF(INDEX(_xlfn._xlws.FILTER(Bewerbungsübersicht!R$2:R$100,(Bewerbungsübersicht!$V$2:$V$100="ja")),ROWS($A$2:A7))=0,"",INDEX(_xlfn._xlws.FILTER(Bewerbungsübersicht!R$2:R$100,(Bewerbungsübersicht!$V$2:$V$100="ja")),ROWS($A$2:A7))),"") | S7: =IFERROR(IF(INDEX(_xlfn._xlws.FILTER(Bewerbungsübersicht!S$2:S$100,(Bewerbungsübersicht!$V$2:$V$100="ja")),ROWS($A$2:A7))=0,"",INDEX(_xlfn._xlws.FILTER(Bewerbungsübersicht!S$2:S$100,(Bewerbungsübersicht!$V$2:$V$100="ja")),ROWS($A$2:A7))),"") | T7: =IFERROR(IF(INDEX(_xlfn._xlws.FILTER(Bewerbungsübersicht!T$2:T$100,(Bewerbungsübersicht!$V$2:$V$100="ja")),ROWS($A$2:A7))=0,"",INDEX(_xlfn._xlws.FILTER(Bewerbungsübersicht!T$2:T$100,(Bewerbungsübersicht!$V$2:$V$100="ja")),ROWS($A$2:A7))),"") | U7: =IFERROR(IF(INDEX(_xlfn._xlws.FILTER(Bewerbungsübersicht!U$2:U$100,(Bewerbungsübersicht!$V$2:$V$100="ja")),ROWS($A$2:A7))=0,"",INDEX(_xlfn._xlws.FILTER(Bewerbungsübersicht!U$2:U$100,(Bewerbungsübersicht!$V$2:$V$100="ja")),ROWS($A$2:A7))),"") | V7: =IFERROR(IF(INDEX(_xlfn._xlws.FILTER(Bewerbungsübersicht!V$2:V$100,(Bewerbungsübersicht!$V$2:$V$100="ja")),ROWS($A$2:A7))=0,"",INDEX(_xlfn._xlws.FILTER(Bewerbungsübersicht!V$2:V$100,(Bewerbungsübersicht!$V$2:$V$100="ja")),ROWS($A$2:A7))),"")
A8: =IFERROR(IF(INDEX(_xlfn._xlws.FILTER(Bewerbungsübersicht!A$2:A$100,(Bewerbungsübersicht!$V$2:$V$100="ja")),ROWS($A$2:A8))=0,"",INDEX(_xlfn._xlws.FILTER(Bewerbungsübersicht!A$2:A$100,(Bewerbungsübersicht!$V$2:$V$100="ja")),ROWS($A$2:A8))),"") | B8: =IFERROR(IF(INDEX(_xlfn._xlws.FILTER(Bewerbungsübersicht!B$2:B$100,(Bewerbungsübersicht!$V$2:$V$100="ja")),ROWS($A$2:A8))=0,"",INDEX(_xlfn._xlws.FILTER(Bewerbungsübersicht!B$2:B$100,(Bewerbungsübersicht!$V$2:$V$100="ja")),ROWS($A$2:A8))),"") | C8: =IFERROR(IF(INDEX(_xlfn._xlws.FILTER(Bewerbungsübersicht!C$2:C$100,(Bewerbungsübersicht!$V$2:$V$100="ja")),ROWS($A$2:A8))=0,"",INDEX(_xlfn._xlws.FILTER(Bewerbungsübersicht!C$2:C$100,(Bewerbungsübersicht!$V$2:$V$100="ja")),ROWS($A$2:A8))),"") | D8: =IFERROR(IF(INDEX(_xlfn._xlws.FILTER(Bewerbungsübersicht!D$2:D$100,(Bewerbungsübersicht!$V$2:$V$100="ja")),ROWS($A$2:A8))=0,"",INDEX(_xlfn._xlws.FILTER(Bewerbungsübersicht!D$2:D$100,(Bewerbungsübersicht!$V$2:$V$100="ja")),ROWS($A$2:A8))),"") | E8: =IFERROR(IF(INDEX(_xlfn._xlws.FILTER(Bewerbungsübersicht!E$2:E$100,(Bewerbungsübersicht!$V$2:$V$100="ja")),ROWS($A$2:A8))=0,"",INDEX(_xlfn._xlws.FILTER(Bewerbungsübersicht!E$2:E$100,(Bewerbungsübersicht!$V$2:$V$100="ja")),ROWS($A$2:A8))),"") | F8: =IFERROR(IF(INDEX(_xlfn._xlws.FILTER(Bewerbungsübersicht!F$2:F$100,(Bewerbungsübersicht!$V$2:$V$100="ja")),ROWS($A$2:A8))=0,"",INDEX(_xlfn._xlws.FILTER(Bewerbungsübersicht!F$2:F$100,(Bewerbungsübersicht!$V$2:$V$100="ja")),ROWS($A$2:A8))),"") | G8: =IFERROR(IF(INDEX(_xlfn._xlws.FILTER(Bewerbungsübersicht!G$2:G$100,(Bewerbungsübersicht!$V$2:$V$100="ja")),ROWS($A$2:A8))=0,"",INDEX(_xlfn._xlws.FILTER(Bewerbungsübersicht!G$2:G$100,(Bewerbungsübersicht!$V$2:$V$100="ja")),ROWS($A$2:A8))),"") | H8: =IFERROR(IF(INDEX(_xlfn._xlws.FILTER(Bewerbungsübersicht!H$2:H$100,(Bewerbungsübersicht!$V$2:$V$100="ja")),ROWS($A$2:A8))=0,"",INDEX(_xlfn._xlws.FILTER(Bewerbungsübersicht!H$2:H$100,(Bewerbungsübersicht!$V$2:$V$100="ja")),ROWS($A$2:A8))),"") | I8: =IFERROR(IF(INDEX(_xlfn._xlws.FILTER(Bewerbungsübersicht!I$2:I$100,(Bewerbungsübersicht!$V$2:$V$100="ja")),ROWS($A$2:A8))=0,"",INDEX(_xlfn._xlws.FILTER(Bewerbungsübersicht!I$2:I$100,(Bewerbungsübersicht!$V$2:$V$100="ja")),ROWS($A$2:A8))),"") | J8: =IFERROR(IF(INDEX(_xlfn._xlws.FILTER(Bewerbungsübersicht!J$2:J$100,(Bewerbungsübersicht!$V$2:$V$100="ja")),ROWS($A$2:A8))=0,"",INDEX(_xlfn._xlws.FILTER(Bewerbungsübersicht!J$2:J$100,(Bewerbungsübersicht!$V$2:$V$100="ja")),ROWS($A$2:A8))),"") | K8: =IFERROR(IF(INDEX(_xlfn._xlws.FILTER(Bewerbungsübersicht!K$2:K$100,(Bewerbungsübersicht!$V$2:$V$100="ja")),ROWS($A$2:A8))=0,"",INDEX(_xlfn._xlws.FILTER(Bewerbungsübersicht!K$2:K$100,(Bewerbungsübersicht!$V$2:$V$100="ja")),ROWS($A$2:A8))),"") | L8: =IFERROR(IF(INDEX(_xlfn._xlws.FILTER(Bewerbungsübersicht!L$2:L$100,(Bewerbungsübersicht!$V$2:$V$100="ja")),ROWS($A$2:A8))=0,"",INDEX(_xlfn._xlws.FILTER(Bewerbungsübersicht!L$2:L$100,(Bewerbungsübersicht!$V$2:$V$100="ja")),ROWS($A$2:A8))),"") | M8: =IFERROR(IF(INDEX(_xlfn._xlws.FILTER(Bewerbungsübersicht!M$2:M$100,(Bewerbungsübersicht!$V$2:$V$100="ja")),ROWS($A$2:A8))=0,"",INDEX(_xlfn._xlws.FILTER(Bewerbungsübersicht!M$2:M$100,(Bewerbungsübersicht!$V$2:$V$100="ja")),ROWS($A$2:A8))),"") | N8: =IFERROR(IF(INDEX(_xlfn._xlws.FILTER(Bewerbungsübersicht!N$2:N$100,(Bewerbungsübersicht!$V$2:$V$100="ja")),ROWS($A$2:A8))=0,"",INDEX(_xlfn._xlws.FILTER(Bewerbungsübersicht!N$2:N$100,(Bewerbungsübersicht!$V$2:$V$100="ja")),ROWS($A$2:A8))),"") | O8: =IFERROR(IF(INDEX(_xlfn._xlws.FILTER(Bewerbungsübersicht!O$2:O$100,(Bewerbungsübersicht!$V$2:$V$100="ja")),ROWS($A$2:A8))=0,"",INDEX(_xlfn._xlws.FILTER(Bewerbungsübersicht!O$2:O$100,(Bewerbungsübersicht!$V$2:$V$100="ja")),ROWS($A$2:A8))),"") | P8: =IFERROR(IF(INDEX(_xlfn._xlws.FILTER(Bewerbungsübersicht!P$2:P$100,(Bewerbungsübersicht!$V$2:$V$100="ja")),ROWS($A$2:A8))=0,"",INDEX(_xlfn._xlws.FILTER(Bewerbungsübersicht!P$2:P$100,(Bewerbungsübersicht!$V$2:$V$100="ja")),ROWS($A$2:A8))),"") | Q8: =IFERROR(IF(INDEX(_xlfn._xlws.FILTER(Bewerbungsübersicht!Q$2:Q$100,(Bewerbungsübersicht!$V$2:$V$100="ja")),ROWS($A$2:A8))=0,"",INDEX(_xlfn._xlws.FILTER(Bewerbungsübersicht!Q$2:Q$100,(Bewerbungsübersicht!$V$2:$V$100="ja")),ROWS($A$2:A8))),"") | R8: =IFERROR(IF(INDEX(_xlfn._xlws.FILTER(Bewerbungsübersicht!R$2:R$100,(Bewerbungsübersicht!$V$2:$V$100="ja")),ROWS($A$2:A8))=0,"",INDEX(_xlfn._xlws.FILTER(Bewerbungsübersicht!R$2:R$100,(Bewerbungsübersicht!$V$2:$V$100="ja")),ROWS($A$2:A8))),"") | S8: =IFERROR(IF(INDEX(_xlfn._xlws.FILTER(Bewerbungsübersicht!S$2:S$100,(Bewerbungsübersicht!$V$2:$V$100="ja")),ROWS($A$2:A8))=0,"",INDEX(_xlfn._xlws.FILTER(Bewerbungsübersicht!S$2:S$100,(Bewerbungsübersicht!$V$2:$V$100="ja")),ROWS($A$2:A8))),"") | T8: =IFERROR(IF(INDEX(_xlfn._xlws.FILTER(Bewerbungsübersicht!T$2:T$100,(Bewerbungsübersicht!$V$2:$V$100="ja")),ROWS($A$2:A8))=0,"",INDEX(_xlfn._xlws.FILTER(Bewerbungsübersicht!T$2:T$100,(Bewerbungsübersicht!$V$2:$V$100="ja")),ROWS($A$2:A8))),"") | U8: =IFERROR(IF(INDEX(_xlfn._xlws.FILTER(Bewerbungsübersicht!U$2:U$100,(Bewerbungsübersicht!$V$2:$V$100="ja")),ROWS($A$2:A8))=0,"",INDEX(_xlfn._xlws.FILTER(Bewerbungsübersicht!U$2:U$100,(Bewerbungsübersicht!$V$2:$V$100="ja")),ROWS($A$2:A8))),"") | V8: =IFERROR(IF(INDEX(_xlfn._xlws.FILTER(Bewerbungsübersicht!V$2:V$100,(Bewerbungsübersicht!$V$2:$V$100="ja")),ROWS($A$2:A8))=0,"",INDEX(_xlfn._xlws.FILTER(Bewerbungsübersicht!V$2:V$100,(Bewerbungsübersicht!$V$2:$V$100="ja")),ROWS($A$2:A8))),"")
A9: =IFERROR(IF(INDEX(_xlfn._xlws.FILTER(Bewerbungsübersicht!A$2:A$100,(Bewerbungsübersicht!$V$2:$V$100="ja")),ROWS($A$2:A9))=0,"",INDEX(_xlfn._xlws.FILTER(Bewerbungsübersicht!A$2:A$100,(Bewerbungsübersicht!$V$2:$V$100="ja")),ROWS($A$2:A9))),"") | B9: =IFERROR(IF(INDEX(_xlfn._xlws.FILTER(Bewerbungsübersicht!B$2:B$100,(Bewerbungsübersicht!$V$2:$V$100="ja")),ROWS($A$2:A9))=0,"",INDEX(_xlfn._xlws.FILTER(Bewerbungsübersicht!B$2:B$100,(Bewerbungsübersicht!$V$2:$V$100="ja")),ROWS($A$2:A9))),"") | C9: =IFERROR(IF(INDEX(_xlfn._xlws.FILTER(Bewerbungsübersicht!C$2:C$100,(Bewerbungsübersicht!$V$2:$V$100="ja")),ROWS($A$2:A9))=0,"",INDEX(_xlfn._xlws.FILTER(Bewerbungsübersicht!C$2:C$100,(Bewerbungsübersicht!$V$2:$V$100="ja")),ROWS($A$2:A9))),"") | D9: =IFERROR(IF(INDEX(_xlfn._xlws.FILTER(Bewerbungsübersicht!D$2:D$100,(Bewerbungsübersicht!$V$2:$V$100="ja")),ROWS($A$2:A9))=0,"",INDEX(_xlfn._xlws.FILTER(Bewerbungsübersicht!D$2:D$100,(Bewerbungsübersicht!$V$2:$V$100="ja")),ROWS($A$2:A9))),"") | E9: =IFERROR(IF(INDEX(_xlfn._xlws.FILTER(Bewerbungsübersicht!E$2:E$100,(Bewerbungsübersicht!$V$2:$V$100="ja")),ROWS($A$2:A9))=0,"",INDEX(_xlfn._xlws.FILTER(Bewerbungsübersicht!E$2:E$100,(Bewerbungsübersicht!$V$2:$V$100="ja")),ROWS($A$2:A9))),"") | F9: =IFERROR(IF(INDEX(_xlfn._xlws.FILTER(Bewerbungsübersicht!F$2:F$100,(Bewerbungsübersicht!$V$2:$V$100="ja")),ROWS($A$2:A9))=0,"",INDEX(_xlfn._xlws.FILTER(Bewerbungsübersicht!F$2:F$100,(Bewerbungsübersicht!$V$2:$V$100="ja")),ROWS($A$2:A9))),"") | G9: =IFERROR(IF(INDEX(_xlfn._xlws.FILTER(Bewerbungsübersicht!G$2:G$100,(Bewerbungsübersicht!$V$2:$V$100="ja")),ROWS($A$2:A9))=0,"",INDEX(_xlfn._xlws.FILTER(Bewerbungsübersicht!G$2:G$100,(Bewerbungsübersicht!$V$2:$V$100="ja")),ROWS($A$2:A9))),"") | H9: =IFERROR(IF(INDEX(_xlfn._xlws.FILTER(Bewerbungsübersicht!H$2:H$100,(Bewerbungsübersicht!$V$2:$V$100="ja")),ROWS($A$2:A9))=0,"",INDEX(_xlfn._xlws.FILTER(Bewerbungsübersicht!H$2:H$100,(Bewerbungsübersicht!$V$2:$V$100="ja")),ROWS($A$2:A9))),"") | I9: =IFERROR(IF(INDEX(_xlfn._xlws.FILTER(Bewerbungsübersicht!I$2:I$100,(Bewerbungsübersicht!$V$2:$V$100="ja")),ROWS($A$2:A9))=0,"",INDEX(_xlfn._xlws.FILTER(Bewerbungsübersicht!I$2:I$100,(Bewerbungsübersicht!$V$2:$V$100="ja")),ROWS($A$2:A9))),"") | J9: =IFERROR(IF(INDEX(_xlfn._xlws.FILTER(Bewerbungsübersicht!J$2:J$100,(Bewerbungsübersicht!$V$2:$V$100="ja")),ROWS($A$2:A9))=0,"",INDEX(_xlfn._xlws.FILTER(Bewerbungsübersicht!J$2:J$100,(Bewerbungsübersicht!$V$2:$V$100="ja")),ROWS($A$2:A9))),"") | K9: =IFERROR(IF(INDEX(_xlfn._xlws.FILTER(Bewerbungsübersicht!K$2:K$100,(Bewerbungsübersicht!$V$2:$V$100="ja")),ROWS($A$2:A9))=0,"",INDEX(_xlfn._xlws.FILTER(Bewerbungsübersicht!K$2:K$100,(Bewerbungsübersicht!$V$2:$V$100="ja")),ROWS($A$2:A9))),"") | L9: =IFERROR(IF(INDEX(_xlfn._xlws.FILTER(Bewerbungsübersicht!L$2:L$100,(Bewerbungsübersicht!$V$2:$V$100="ja")),ROWS($A$2:A9))=0,"",INDEX(_xlfn._xlws.FILTER(Bewerbungsübersicht!L$2:L$100,(Bewerbungsübersicht!$V$2:$V$100="ja")),ROWS($A$2:A9))),"") | M9: =IFERROR(IF(INDEX(_xlfn._xlws.FILTER(Bewerbungsübersicht!M$2:M$100,(Bewerbungsübersicht!$V$2:$V$100="ja")),ROWS($A$2:A9))=0,"",INDEX(_xlfn._xlws.FILTER(Bewerbungsübersicht!M$2:M$100,(Bewerbungsübersicht!$V$2:$V$100="ja")),ROWS($A$2:A9))),"") | N9: =IFERROR(IF(INDEX(_xlfn._xlws.FILTER(Bewerbungsübersicht!N$2:N$100,(Bewerbungsübersicht!$V$2:$V$100="ja")),ROWS($A$2:A9))=0,"",INDEX(_xlfn._xlws.FILTER(Bewerbungsübersicht!N$2:N$100,(Bewerbungsübersicht!$V$2:$V$100="ja")),ROWS($A$2:A9))),"") | O9: =IFERROR(IF(INDEX(_xlfn._xlws.FILTER(Bewerbungsübersicht!O$2:O$100,(Bewerbungsübersicht!$V$2:$V$100="ja")),ROWS($A$2:A9))=0,"",INDEX(_xlfn._xlws.FILTER(Bewerbungsübersicht!O$2:O$100,(Bewerbungsübersicht!$V$2:$V$100="ja")),ROWS($A$2:A9))),"") | P9: =IFERROR(IF(INDEX(_xlfn._xlws.FILTER(Bewerbungsübersicht!P$2:P$100,(Bewerbungsübersicht!$V$2:$V$100="ja")),ROWS($A$2:A9))=0,"",INDEX(_xlfn._xlws.FILTER(Bewerbungsübersicht!P$2:P$100,(Bewerbungsübersicht!$V$2:$V$100="ja")),ROWS($A$2:A9))),"") | Q9: =IFERROR(IF(INDEX(_xlfn._xlws.FILTER(Bewerbungsübersicht!Q$2:Q$100,(Bewerbungsübersicht!$V$2:$V$100="ja")),ROWS($A$2:A9))=0,"",INDEX(_xlfn._xlws.FILTER(Bewerbungsübersicht!Q$2:Q$100,(Bewerbungsübersicht!$V$2:$V$100="ja")),ROWS($A$2:A9))),"") | R9: =IFERROR(IF(INDEX(_xlfn._xlws.FILTER(Bewerbungsübersicht!R$2:R$100,(Bewerbungsübersicht!$V$2:$V$100="ja")),ROWS($A$2:A9))=0,"",INDEX(_xlfn._xlws.FILTER(Bewerbungsübersicht!R$2:R$100,(Bewerbungsübersicht!$V$2:$V$100="ja")),ROWS($A$2:A9))),"") | S9: =IFERROR(IF(INDEX(_xlfn._xlws.FILTER(Bewerbungsübersicht!S$2:S$100,(Bewerbungsübersicht!$V$2:$V$100="ja")),ROWS($A$2:A9))=0,"",INDEX(_xlfn._xlws.FILTER(Bewerbungsübersicht!S$2:S$100,(Bewerbungsübersicht!$V$2:$V$100="ja")),ROWS($A$2:A9))),"") | T9: =IFERROR(IF(INDEX(_xlfn._xlws.FILTER(Bewerbungsübersicht!T$2:T$100,(Bewerbungsübersicht!$V$2:$V$100="ja")),ROWS($A$2:A9))=0,"",INDEX(_xlfn._xlws.FILTER(Bewerbungsübersicht!T$2:T$100,(Bewerbungsübersicht!$V$2:$V$100="ja")),ROWS($A$2:A9))),"") | U9: =IFERROR(IF(INDEX(_xlfn._xlws.FILTER(Bewerbungsübersicht!U$2:U$100,(Bewerbungsübersicht!$V$2:$V$100="ja")),ROWS($A$2:A9))=0,"",INDEX(_xlfn._xlws.FILTER(Bewerbungsübersicht!U$2:U$100,(Bewerbungsübersicht!$V$2:$V$100="ja")),ROWS($A$2:A9))),"") | V9: =IFERROR(IF(INDEX(_xlfn._xlws.FILTER(Bewerbungsübersicht!V$2:V$100,(Bewerbungsübersicht!$V$2:$V$100="ja")),ROWS($A$2:A9))=0,"",INDEX(_xlfn._xlws.FILTER(Bewerbungsübersicht!V$2:V$100,(Bewerbungsübersicht!$V$2:$V$100="ja")),ROWS($A$2:A9))),"")
A10: =IFERROR(IF(INDEX(_xlfn._xlws.FILTER(Bewerbungsübersicht!A$2:A$100,(Bewerbungsübersicht!$V$2:$V$100="ja")),ROWS($A$2:A10))=0,"",INDEX(_xlfn._xlws.FILTER(Bewerbungsübersicht!A$2:A$100,(Bewerbungsübersicht!$V$2:$V$100="ja")),ROWS($A$2:A10))),"") | B10: =IFERROR(IF(INDEX(_xlfn._xlws.FILTER(Bewerbungsübersicht!B$2:B$100,(Bewerbungsübersicht!$V$2:$V$100="ja")),ROWS($A$2:A10))=0,"",INDEX(_xlfn._xlws.FILTER(Bewerbungsübersicht!B$2:B$100,(Bewerbungsübersicht!$V$2:$V$100="ja")),ROWS($A$2:A10))),"") | C10: =IFERROR(IF(INDEX(_xlfn._xlws.FILTER(Bewerbungsübersicht!C$2:C$100,(Bewerbungsübersicht!$V$2:$V$100="ja")),ROWS($A$2:A10))=0,"",INDEX(_xlfn._xlws.FILTER(Bewerbungsübersicht!C$2:C$100,(Bewerbungsübersicht!$V$2:$V$100="ja")),ROWS($A$2:A10))),"") | D10: =IFERROR(IF(INDEX(_xlfn._xlws.FILTER(Bewerbungsübersicht!D$2:D$100,(Bewerbungsübersicht!$V$2:$V$100="ja")),ROWS($A$2:A10))=0,"",INDEX(_xlfn._xlws.FILTER(Bewerbungsübersicht!D$2:D$100,(Bewerbungsübersicht!$V$2:$V$100="ja")),ROWS($A$2:A10))),"") | E10: =IFERROR(IF(INDEX(_xlfn._xlws.FILTER(Bewerbungsübersicht!E$2:E$100,(Bewerbungsübersicht!$V$2:$V$100="ja")),ROWS($A$2:A10))=0,"",INDEX(_xlfn._xlws.FILTER(Bewerbungsübersicht!E$2:E$100,(Bewerbungsübersicht!$V$2:$V$100="ja")),ROWS($A$2:A10))),"") | F10: =IFERROR(IF(INDEX(_xlfn._xlws.FILTER(Bewerbungsübersicht!F$2:F$100,(Bewerbungsübersicht!$V$2:$V$100="ja")),ROWS($A$2:A10))=0,"",INDEX(_xlfn._xlws.FILTER(Bewerbungsübersicht!F$2:F$100,(Bewerbungsübersicht!$V$2:$V$100="ja")),ROWS($A$2:A10))),"") | G10: =IFERROR(IF(INDEX(_xlfn._xlws.FILTER(Bewerbungsübersicht!G$2:G$100,(Bewerbungsübersicht!$V$2:$V$100="ja")),ROWS($A$2:A10))=0,"",INDEX(_xlfn._xlws.FILTER(Bewerbungsübersicht!G$2:G$100,(Bewerbungsübersicht!$V$2:$V$100="ja")),ROWS($A$2:A10))),"") | H10: =IFERROR(IF(INDEX(_xlfn._xlws.FILTER(Bewerbungsübersicht!H$2:H$100,(Bewerbungsübersicht!$V$2:$V$100="ja")),ROWS($A$2:A10))=0,"",INDEX(_xlfn._xlws.FILTER(Bewerbungsübersicht!H$2:H$100,(Bewerbungsübersicht!$V$2:$V$100="ja")),ROWS($A$2:A10))),"") | I10: =IFERROR(IF(INDEX(_xlfn._xlws.FILTER(Bewerbungsübersicht!I$2:I$100,(Bewerbungsübersicht!$V$2:$V$100="ja")),ROWS($A$2:A10))=0,"",INDEX(_xlfn._xlws.FILTER(Bewerbungsübersicht!I$2:I$100,(Bewerbungsübersicht!$V$2:$V$100="ja")),ROWS($A$2:A10))),"") | J10: =IFERROR(IF(INDEX(_xlfn._xlws.FILTER(Bewerbungsübersicht!J$2:J$100,(Bewerbungsübersicht!$V$2:$V$100="ja")),ROWS($A$2:A10))=0,"",INDEX(_xlfn._xlws.FILTER(Bewerbungsübersicht!J$2:J$100,(Bewerbungsübersicht!$V$2:$V$100="ja")),ROWS($A$2:A10))),"") | K10: =IFERROR(IF(INDEX(_xlfn._xlws.FILTER(Bewerbungsübersicht!K$2:K$100,(Bewerbungsübersicht!$V$2:$V$100="ja")),ROWS($A$2:A10))=0,"",INDEX(_xlfn._xlws.FILTER(Bewerbungsübersicht!K$2:K$100,(Bewerbungsübersicht!$V$2:$V$100="ja")),ROWS($A$2:A10))),"") | L10: =IFERROR(IF(INDEX(_xlfn._xlws.FILTER(Bewerbungsübersicht!L$2:L$100,(Bewerbungsübersicht!$V$2:$V$100="ja")),ROWS($A$2:A10))=0,"",INDEX(_xlfn._xlws.FILTER(Bewerbungsübersicht!L$2:L$100,(Bewerbungsübersicht!$V$2:$V$100="ja")),ROWS($A$2:A10))),"") | M10: =IFERROR(IF(INDEX(_xlfn._xlws.FILTER(Bewerbungsübersicht!M$2:M$100,(Bewerbungsübersicht!$V$2:$V$100="ja")),ROWS($A$2:A10))=0,"",INDEX(_xlfn._xlws.FILTER(Bewerbungsübersicht!M$2:M$100,(Bewerbungsübersicht!$V$2:$V$100="ja")),ROWS($A$2:A10))),"") | N10: =IFERROR(IF(INDEX(_xlfn._xlws.FILTER(Bewerbungsübersicht!N$2:N$100,(Bewerbungsübersicht!$V$2:$V$100="ja")),ROWS($A$2:A10))=0,"",INDEX(_xlfn._xlws.FILTER(Bewerbungsübersicht!N$2:N$100,(Bewerbungsübersicht!$V$2:$V$100="ja")),ROWS($A$2:A10))),"") | O10: =IFERROR(IF(INDEX(_xlfn._xlws.FILTER(Bewerbungsübersicht!O$2:O$100,(Bewerbungsübersicht!$V$2:$V$100="ja")),ROWS($A$2:A10))=0,"",INDEX(_xlfn._xlws.FILTER(Bewerbungsübersicht!O$2:O$100,(Bewerbungsübersicht!$V$2:$V$100="ja")),ROWS($A$2:A10))),"") | P10: =IFERROR(IF(INDEX(_xlfn._xlws.FILTER(Bewerbungsübersicht!P$2:P$100,(Bewerbungsübersicht!$V$2:$V$100="ja")),ROWS($A$2:A10))=0,"",INDEX(_xlfn._xlws.FILTER(Bewerbungsübersicht!P$2:P$100,(Bewerbungsübersicht!$V$2:$V$100="ja")),ROWS($A$2:A10))),"") | Q10: =IFERROR(IF(INDEX(_xlfn._xlws.FILTER(Bewerbungsübersicht!Q$2:Q$100,(Bewerbungsübersicht!$V$2:$V$100="ja")),ROWS($A$2:A10))=0,"",INDEX(_xlfn._xlws.FILTER(Bewerbungsübersicht!Q$2:Q$100,(Bewerbungsübersicht!$V$2:$V$100="ja")),ROWS($A$2:A10))),"") | R10: =IFERROR(IF(INDEX(_xlfn._xlws.FILTER(Bewerbungsübersicht!R$2:R$100,(Bewerbungsübersicht!$V$2:$V$100="ja")),ROWS($A$2:A10))=0,"",INDEX(_xlfn._xlws.FILTER(Bewerbungsübersicht!R$2:R$100,(Bewerbungsübersicht!$V$2:$V$100="ja")),ROWS($A$2:A10))),"") | S10: =IFERROR(IF(INDEX(_xlfn._xlws.FILTER(Bewerbungsübersicht!S$2:S$100,(Bewerbungsübersicht!$V$2:$V$100="ja")),ROWS($A$2:A10))=0,"",INDEX(_xlfn._xlws.FILTER(Bewerbungsübersicht!S$2:S$100,(Bewerbungsübersicht!$V$2:$V$100="ja")),ROWS($A$2:A10))),"") | T10: =IFERROR(IF(INDEX(_xlfn._xlws.FILTER(Bewerbungsübersicht!T$2:T$100,(Bewerbungsübersicht!$V$2:$V$100="ja")),ROWS($A$2:A10))=0,"",INDEX(_xlfn._xlws.FILTER(Bewerbungsübersicht!T$2:T$100,(Bewerbungsübersicht!$V$2:$V$100="ja")),ROWS($A$2:A10))),"") | U10: =IFERROR(IF(INDEX(_xlfn._xlws.FILTER(Bewerbungsübersicht!U$2:U$100,(Bewerbungsübersicht!$V$2:$V$100="ja")),ROWS($A$2:A10))=0,"",INDEX(_xlfn._xlws.FILTER(Bewerbungsübersicht!U$2:U$100,(Bewerbungsübersicht!$V$2:$V$100="ja")),ROWS($A$2:A10))),"") | V10: =IFERROR(IF(INDEX(_xlfn._xlws.FILTER(Bewerbungsübersicht!V$2:V$100,(Bewerbungsübersicht!$V$2:$V$100="ja")),ROWS($A$2:A10))=0,"",INDEX(_xlfn._xlws.FILTER(Bewerbungsübersicht!V$2:V$100,(Bewerbungsübersicht!$V$2:$V$100="ja")),ROWS($A$2:A10))),"")
